<?xml version="1.0"?>
<robot name="buddy" xmlns:xacro="http://ros.org/wiki/xacro">

  <link name="base_footprint" />
  <joint name="base_footprint_joint" type="fixed">
    <parent link="base_footprint" />
    <child link="base_link" />
    <origin xyz="0 0 0.210" rpy="0 0 0" />
  </joint>

  <link name="base_link">
    <visual>
      <geometry>
        <box size="0.70 0.92 0.23" />
      </geometry>
      <material name="silver">
        <color rgba="0.75 0.75 0.75 1" />
      </material>
    </visual>
    <collision>
      <geometry>
        <box size="0.70 0.92 0.23" />
      </geometry>
    </collision>
    <inertial>
      <mass value="15.0" />
      <inertia ixx="1.12" ixy="0.0" ixz="0.0" iyy="0.68" iyz="0.0" izz="1.67" />
    </inertial>
  </link>

  <link name="front_left_wheel">
    <visual>
      <geometry>
        <cylinder radius="0.125" length="0.08" />
      </geometry>
      <material name="black">
        <color rgba="0.0 0.0 0.0 1" />
      </material>
    </visual>
    <collision>
      <geometry>
        <cylinder radius="0.125" length="0.08" />
      </geometry>
    </collision>
    <inertial>
      <mass value="1.0" />
      <inertia ixx="0.004" ixy="0" ixz="0" iyy="0.004" iyz="0" izz="0.008" />
    </inertial>
  </link>

  <joint name="front_left_wheel_joint" type="continuous">
    <parent link="base_link" />
    <child link="front_left_wheel" />
    <origin xyz="0.1825 0.50 -0.085" rpy="-1.5707 0 0" />
    <axis xyz="0 0 1" />
  </joint>

  <link name="front_right_wheel">
    <visual>
      <geometry>
        <cylinder radius="0.125" length="0.08" />
      </geometry>
      <material name="black" />
    </visual>
    <collision>
      <geometry>
        <cylinder radius="0.125" length="0.08" />
      </geometry>
    </collision>
    <inertial>
      <mass value="1.0" />
      <inertia ixx="0.004" ixy="0" ixz="0" iyy="0.004" iyz="0" izz="0.008" />
    </inertial>
  </link>

  <joint name="front_right_wheel_joint" type="continuous">
    <parent link="base_link" />
    <child link="front_right_wheel" />
    <origin xyz="0.1825 -0.50 -0.085" rpy="-1.5707 0 0" />
    <axis xyz="0 0 1" />
  </joint>

  <link name="rear_left_wheel">
    <visual>
      <geometry>
        <cylinder radius="0.125" length="0.08" />
      </geometry>
      <material name="black" />
    </visual>
    <collision>
      <geometry>
        <cylinder radius="0.125" length="0.08" />
      </geometry>
    </collision>
    <inertial>
      <mass value="1.0" />
      <inertia ixx="0.004" ixy="0" ixz="0" iyy="0.004" iyz="0" izz="0.008" />
    </inertial>
  </link>

  <joint name="rear_left_wheel_joint" type="continuous">
    <parent link="base_link" />
    <child link="rear_left_wheel" />
    <origin xyz="-0.1825 0.50 -0.085" rpy="-1.5707 0 0" />
    <axis xyz="0 0 1" />
  </joint>

  <link name="rear_right_wheel">
    <visual>
      <geometry>
        <cylinder radius="0.125" length="0.08" />
      </geometry>
      <material name="black" />
    </visual>
    <collision>
      <geometry>
        <cylinder radius="0.125" length="0.08" />
      </geometry>
    </collision>
    <inertial>
      <mass value="1.0" />
      <inertia ixx="0.004" ixy="0" ixz="0" iyy="0.004" iyz="0" izz="0.008" />
    </inertial>
  </link>

  <joint name="rear_right_wheel_joint" type="continuous">
    <parent link="base_link" />
    <child link="rear_right_wheel" />
    <origin xyz="-0.1825 -0.50 -0.085" rpy="-1.5707 0 0" />
    <axis xyz="0 0 1" />
  </joint>

  <link name="lidar_link">
    <visual>
      <geometry>
        <cylinder radius="0.05" length="0.06" />
      </geometry>
      <material name="blue">
        <color rgba="0.0 0.0 1.0 1" />
      </material>
    </visual>
    <collision>
      <geometry>
        <cylinder radius="0.05" length="0.06" />
      </geometry>
    </collision>
    <inertial>
      <mass value="0.2" />
      <inertia ixx="0.0001" ixy="0" ixz="0" iyy="0.0001" iyz="0" izz="0.0002" />
    </inertial>
  </link>

  <joint name="lidar_joint" type="fixed">
    <parent link="base_link" />
    <child link="lidar_link" />
    <origin xyz="0.3 0 0.145" rpy="0 0 0" />
  </joint>

  <link name="imu_link">
    <visual>
      <geometry>
        <box size="0.02 0.02 0.01" />
      </geometry>
      <material name="red">
        <color rgba="1.0 0.0 0.0 1" />
      </material>
    </visual>
    <collision>
      <geometry>
        <box size="0.02 0.02 0.01" />
      </geometry>
    </collision>
    <inertial>
      <mass value="0.01" />
      <inertia ixx="0.000001" ixy="0" ixz="0" iyy="0.000001" iyz="0" izz="0.000001" />
    </inertial>
  </link>

  <joint name="imu_joint" type="fixed">
    <parent link="base_link" />
    <child link="imu_link" />
    <origin xyz="0 0 0.12" rpy="0 0 0" />
  </joint>

  <gazebo>
    <plugin filename="libignition-gazebo-diff-drive-system.so"
      name="ignition::gazebo::systems::DiffDrive">
      <left_joint>front_left_wheel_joint</left_joint>
      <left_joint>rear_left_wheel_joint</left_joint>
      <right_joint>front_right_wheel_joint</right_joint>
      <right_joint>rear_right_wheel_joint</right_joint>

      <wheel_separation>1.0</wheel_separation>
      <wheel_radius>0.125</wheel_radius>

      <odom_publish_frequency>50</odom_publish_frequency>
      <topic>cmd_vel</topic>
      <odom_topic>odom</odom_topic>
      <frame_id>odom</frame_id>
      <child_frame_id>base_footprint</child_frame_id>
    </plugin>
  </gazebo>

  <gazebo reference="lidar_link">
    <sensor name="rplidar" type="gpu_lidar">
      <pose>0 0 0 0 0 0</pose>
      <topic>scan</topic>
      <ignition_frame_id>lidar_link</ignition_frame_id>
      <update_rate>10</update_rate>
      <ray>
        <scan>
          <horizontal>
            <samples>360</samples>
            <resolution>1</resolution>
            <min_angle>-3.14159</min_angle>
            <max_angle>3.14159</max_angle>
          </horizontal>
        </scan>
        <range>
          <min>0.15</min>
          <max>12.0</max>
          <resolution>0.01</resolution>
        </range>
      </ray>
      <always_on>true</always_on>
      <visualize>true</visualize>
    </sensor>
  </gazebo>

  <gazebo reference="imu_link">
    <sensor name="imu_sensor" type="imu">
      <always_on>true</always_on>
      <update_rate>100</update_rate>
      <topic>imu</topic>
      <pose>0 0 0 0 0 0</pose>
    </sensor>
  </gazebo>

</robot>